multiprocessing.pool.RemoteTraceback:
"""
Traceback (most recent call last):
  File "/home/josyula/miniconda3/lib/python3.9/multiprocessing/pool.py", line 125, in worker
    result = (True, func(*args, **kwds))
  File "/home/josyula/miniconda3/lib/python3.9/multiprocessing/pool.py", line 48, in mapstar
    return list(map(*args))
TypeError: mutate_individual() missing 1 required positional argument: 'individual'
"""
The above exception was the direct cause of the following exception:
Traceback (most recent call last):
  File "/home/josyula/Programs/pycharm-2022.2.3/plugins/python/helpers/pydev/pydevd.py", line 1496, in _exec
    pydev_imports.execfile(file, globals, locals)  # execute the script
  File "/home/josyula/Programs/pycharm-2022.2.3/plugins/python/helpers/pydev/_pydev_imps/_pydev_execfile.py", line 18, in execfile
    exec(compile(contents+"\n", file, 'exec'), glob, loc)
  File "/home/josyula/Programs/MAS_Project/gym_envs_urdf/examples/neurocoevolution_pytorch/main.py", line 14, in <module>
    trainer.step()
  File "/home/josyula/Programs/MAS_Project/gym_envs_urdf/examples/neurocoevolution_pytorch/algorithms/trainer_es.py", line 62, in step
    mutations_player1 += [mutation_pool.map(self.worker_class.mutate_individual, [self.player1_hof[i]] * self.n)]
  File "/home/josyula/miniconda3/lib/python3.9/multiprocessing/pool.py", line 364, in map
    return self._map_async(func, iterable, mapstar, chunksize).get()
  File "/home/josyula/miniconda3/lib/python3.9/multiprocessing/pool.py", line 771, in get
    raise self._value
TypeError: mutate_individual() missing 1 required positional argument: 'individual'
multiprocessing.pool.RemoteTraceback:
"""
Traceback (most recent call last):
  File "/home/josyula/miniconda3/lib/python3.9/multiprocessing/pool.py", line 125, in worker
    result = (True, func(*args, **kwds))
  File "/home/josyula/miniconda3/lib/python3.9/multiprocessing/pool.py", line 48, in mapstar
    return list(map(*args))
TypeError: mutate_individual() missing 1 required positional argument: 'individual'
"""
The above exception was the direct cause of the following exception:
Traceback (most recent call last):
  File "/home/josyula/Programs/pycharm-2022.2.3/plugins/python/helpers/pydev/pydevd.py", line 2195, in <module>
    main()
  File "/home/josyula/Programs/pycharm-2022.2.3/plugins/python/helpers/pydev/pydevd.py", line 2177, in main
    globals = debugger.run(setup['file'], None, None, is_module)
  File "/home/josyula/Programs/pycharm-2022.2.3/plugins/python/helpers/pydev/pydevd.py", line 1489, in run
    return self._exec(is_module, entry_point_fn, module_name, file, globals, locals)
  File "/home/josyula/Programs/pycharm-2022.2.3/plugins/python/helpers/pydev/pydevd.py", line 1496, in _exec
    pydev_imports.execfile(file, globals, locals)  # execute the script
  File "/home/josyula/Programs/pycharm-2022.2.3/plugins/python/helpers/pydev/_pydev_imps/_pydev_execfile.py", line 18, in execfile
    exec(compile(contents+"\n", file, 'exec'), glob, loc)
  File "/home/josyula/Programs/MAS_Project/gym_envs_urdf/examples/neurocoevolution_pytorch/main.py", line 14, in <module>
    trainer.step()
  File "/home/josyula/Programs/MAS_Project/gym_envs_urdf/examples/neurocoevolution_pytorch/algorithms/trainer_es.py", line 62, in step
    mutations_player1 += [mutation_pool.map(self.worker_class.mutate_individual, [self.player1_hof[i]] * self.n)]
  File "/home/josyula/miniconda3/lib/python3.9/multiprocessing/pool.py", line 364, in map
    return self._map_async(func, iterable, mapstar, chunksize).get()
  File "/home/josyula/miniconda3/lib/python3.9/multiprocessing/pool.py", line 771, in get
    raise self._value
TypeError: mutate_individual() missing 1 required positional argument: 'individual'