2022-11-13 13:13:47,882 INFO    MainThread:16620 [internal.py:wandb_internal():87] W&B internal server running at pid: 16620, started at: 2022-11-13 13:13:47.882582
2022-11-13 13:13:47,884 DEBUG   HandlerThread:16620 [handler.py:handle_request():130] handle_request: check_version
2022-11-13 13:13:47,885 INFO    WriterThread:16620 [datastore.py:open_for_write():77] open: /home/josyula/Programs/MAS_Project/gym_envs_urdf/examples/MADDPG/wandb/run-20221113_131346-9tjc5tzn/run-9tjc5tzn.wandb
2022-11-13 13:13:47,887 DEBUG   SenderThread:16620 [sender.py:send():234] send: header
2022-11-13 13:13:47,887 DEBUG   SenderThread:16620 [sender.py:send_request():248] send_request: check_version
2022-11-13 13:13:47,948 DEBUG   SenderThread:16620 [sender.py:send():234] send: run
2022-11-13 13:13:48,150 ERROR   SenderThread:16620 [internal_api.py:execute():144] 404 response executing GraphQL.
2022-11-13 13:13:48,151 ERROR   SenderThread:16620 [internal_api.py:execute():145] {"errors":[{"message":"entity maddpg not found during upsertBucket","path":["upsertBucket"]}],"data":{"upsertBucket":null}}
2022-11-13 13:13:48,949 INFO    HandlerThread:16620 [handler.py:finish():731] shutting down handler
2022-11-13 13:13:48,949 INFO    WriterThread:16620 [datastore.py:close():281] close: /home/josyula/Programs/MAS_Project/gym_envs_urdf/examples/MADDPG/wandb/run-20221113_131346-9tjc5tzn/run-9tjc5tzn.wandb
2022-11-13 13:13:48,950 ERROR   MainThread:16620 [internal.py:wandb_internal():158] Thread SenderThread:
Traceback (most recent call last):
  File "/home/josyula/miniconda3/lib/python3.9/site-packages/wandb/sdk/lib/retry.py", line 102, in __call__
    result = self._call_fn(*args, **kwargs)
  File "/home/josyula/miniconda3/lib/python3.9/site-packages/wandb/sdk/internal/internal_api.py", line 147, in execute
    six.reraise(*sys.exc_info())
  File "/home/josyula/miniconda3/lib/python3.9/site-packages/six.py", line 703, in reraise
    raise value
  File "/home/josyula/miniconda3/lib/python3.9/site-packages/wandb/sdk/internal/internal_api.py", line 141, in execute
    return self.client.execute(*args, **kwargs)
  File "/home/josyula/miniconda3/lib/python3.9/site-packages/wandb/vendor/gql-0.2.0/gql/client.py", line 52, in execute
    result = self._get_result(document, *args, **kwargs)
  File "/home/josyula/miniconda3/lib/python3.9/site-packages/wandb/vendor/gql-0.2.0/gql/client.py", line 60, in _get_result
    return self.transport.execute(document, *args, **kwargs)
  File "/home/josyula/miniconda3/lib/python3.9/site-packages/wandb/vendor/gql-0.2.0/gql/transport/requests.py", line 39, in execute
    request.raise_for_status()
  File "/home/josyula/miniconda3/lib/python3.9/site-packages/requests/models.py", line 1022, in raise_for_status
    raise HTTPError(http_error_msg, response=self)
requests.exceptions.HTTPError: 404 Client Error: Not Found for url: https://api.wandb.ai/graphql

During handling of the above exception, another exception occurred:

Traceback (most recent call last):
  File "/home/josyula/miniconda3/lib/python3.9/site-packages/wandb/apis/normalize.py", line 24, in wrapper
    return func(*args, **kwargs)
  File "/home/josyula/miniconda3/lib/python3.9/site-packages/wandb/sdk/internal/internal_api.py", line 1298, in upsert_run
    response = self.gql(mutation, variable_values=variable_values, **kwargs)
  File "/home/josyula/miniconda3/lib/python3.9/site-packages/wandb/sdk/lib/retry.py", line 118, in __call__
    if not check_retry_fn(e):
  File "/home/josyula/miniconda3/lib/python3.9/site-packages/wandb/util.py", line 821, in no_retry_auth
    raise CommError("Permission denied, ask the project owner to grant you access")
wandb.errors.CommError: Permission denied, ask the project owner to grant you access

During handling of the above exception, another exception occurred:

Traceback (most recent call last):
  File "/home/josyula/miniconda3/lib/python3.9/site-packages/wandb/sdk/internal/internal_util.py", line 52, in run
    self._run()
  File "/home/josyula/miniconda3/lib/python3.9/site-packages/wandb/sdk/internal/internal_util.py", line 102, in _run
    self._process(record)
  File "/home/josyula/miniconda3/lib/python3.9/site-packages/wandb/sdk/internal/internal.py", line 291, in _process
    self._sm.send(record)
  File "/home/josyula/miniconda3/lib/python3.9/site-packages/wandb/sdk/internal/sender.py", line 236, in send
    send_handler(record)
  File "/home/josyula/miniconda3/lib/python3.9/site-packages/wandb/sdk/internal/sender.py", line 687, in send_run
    self._init_run(run, config_value_dict)
  File "/home/josyula/miniconda3/lib/python3.9/site-packages/wandb/sdk/internal/sender.py", line 711, in _init_run
    server_run, inserted = self._api.upsert_run(
  File "/home/josyula/miniconda3/lib/python3.9/site-packages/wandb/apis/normalize.py", line 62, in wrapper
    six.reraise(CommError, CommError(message, err), sys.exc_info()[2])
  File "/home/josyula/miniconda3/lib/python3.9/site-packages/six.py", line 702, in reraise
    raise value.with_traceback(tb)
  File "/home/josyula/miniconda3/lib/python3.9/site-packages/wandb/apis/normalize.py", line 24, in wrapper
    return func(*args, **kwargs)
  File "/home/josyula/miniconda3/lib/python3.9/site-packages/wandb/sdk/internal/internal_api.py", line 1298, in upsert_run
    response = self.gql(mutation, variable_values=variable_values, **kwargs)
  File "/home/josyula/miniconda3/lib/python3.9/site-packages/wandb/sdk/lib/retry.py", line 118, in __call__
    if not check_retry_fn(e):
  File "/home/josyula/miniconda3/lib/python3.9/site-packages/wandb/util.py", line 821, in no_retry_auth
    raise CommError("Permission denied, ask the project owner to grant you access")
wandb.errors.CommError: Permission denied, ask the project owner to grant you access
2022-11-13 13:13:51,324 INFO    MainThread:16620 [internal.py:handle_exit():77] Internal process exited
