pybullet build time: May 20 2022 19:45:31
pybullet build time: May 20 2022 19:45:31
pybullet build time: May 20 2022 19:45:31
pybullet build time: May 20 2022 19:45:31
Problem at: /home/josyula/Programs/MAS_Project/gym_envs_urdf/examples/neurocoevolution_pytorch/algorithms/trainer_ga.py 17 <module>
Problem at: /home/josyula/Programs/MAS_Project/gym_envs_urdf/examples/neurocoevolution_pytorch/algorithms/trainer_ga.py 17 <module>
Problem at: /home/josyula/Programs/MAS_Project/gym_envs_urdf/examples/neurocoevolution_pytorch/algorithms/trainer_ga.py 17 <module>
Problem at: /home/josyula/Programs/MAS_Project/gym_envs_urdf/examples/neurocoevolution_pytorch/algorithms/trainer_ga.py 17 <module>
[34m[1mwandb[39m[22m: Currently logged in as: [33mjosyulak[39m (use `wandb login --relogin` to force relogin)
[34m[1mwandb[39m[22m: Currently logged in as: [33mjosyulak[39m (use `wandb login --relogin` to force relogin)
Traceback (most recent call last):
  File "/home/josyula/miniconda3/lib/python3.9/site-packages/wandb/sdk/wandb_init.py", line 931, in init
    run = wi.init()
  File "/home/josyula/miniconda3/lib/python3.9/site-packages/wandb/sdk/wandb_init.py", line 467, in init
    backend.ensure_launched()
  File "/home/josyula/miniconda3/lib/python3.9/site-packages/wandb/sdk/backend/backend.py", line 219, in ensure_launched
    self.wandb_process.start()
  File "/home/josyula/miniconda3/lib/python3.9/multiprocessing/process.py", line 121, in start
    self._popen = self._Popen(self)
  File "/home/josyula/miniconda3/lib/python3.9/multiprocessing/context.py", line 284, in _Popen
    return Popen(process_obj)
  File "/home/josyula/miniconda3/lib/python3.9/multiprocessing/popen_spawn_posix.py", line 32, in __init__
    super().__init__(process_obj)
  File "/home/josyula/miniconda3/lib/python3.9/multiprocessing/popen_fork.py", line 19, in __init__
    self._launch(process_obj)
  File "/home/josyula/miniconda3/lib/python3.9/multiprocessing/popen_spawn_posix.py", line 42, in _launch
    prep_data = spawn.get_preparation_data(process_obj._name)
  File "/home/josyula/miniconda3/lib/python3.9/multiprocessing/spawn.py", line 154, in get_preparation_data
    _check_not_importing_main()
  File "/home/josyula/miniconda3/lib/python3.9/multiprocessing/spawn.py", line 134, in _check_not_importing_main
    raise RuntimeError('''
RuntimeError:
        An attempt has been made to start a new process before the
        current process has finished its bootstrapping phase.
        This probably means that you are not using fork to start your
        child processes and you have forgotten to use the proper idiom
        in the main module:
            if __name__ == '__main__':
                freeze_support()
                ...
        The "freeze_support()" line can be omitted if the program
        is not going to be frozen to produce an executable.
[34m[1mwandb[39m[22m: Currently logged in as: [33mjosyulak[39m (use `wandb login --relogin` to force relogin)
Traceback (most recent call last):
  File "/home/josyula/miniconda3/lib/python3.9/site-packages/wandb/sdk/wandb_init.py", line 931, in init
    run = wi.init()
  File "/home/josyula/miniconda3/lib/python3.9/site-packages/wandb/sdk/wandb_init.py", line 467, in init
    backend.ensure_launched()
  File "/home/josyula/miniconda3/lib/python3.9/site-packages/wandb/sdk/backend/backend.py", line 219, in ensure_launched
    self.wandb_process.start()
  File "/home/josyula/miniconda3/lib/python3.9/multiprocessing/process.py", line 121, in start
    self._popen = self._Popen(self)
  File "/home/josyula/miniconda3/lib/python3.9/multiprocessing/context.py", line 284, in _Popen
    return Popen(process_obj)
  File "/home/josyula/miniconda3/lib/python3.9/multiprocessing/popen_spawn_posix.py", line 32, in __init__
    super().__init__(process_obj)
  File "/home/josyula/miniconda3/lib/python3.9/multiprocessing/popen_fork.py", line 19, in __init__
    self._launch(process_obj)
  File "/home/josyula/miniconda3/lib/python3.9/multiprocessing/popen_spawn_posix.py", line 42, in _launch
    prep_data = spawn.get_preparation_data(process_obj._name)
  File "/home/josyula/miniconda3/lib/python3.9/multiprocessing/spawn.py", line 154, in get_preparation_data
    _check_not_importing_main()
  File "/home/josyula/miniconda3/lib/python3.9/multiprocessing/spawn.py", line 134, in _check_not_importing_main
    raise RuntimeError('''
RuntimeError:
        An attempt has been made to start a new process before the
        current process has finished its bootstrapping phase.
        This probably means that you are not using fork to start your
        child processes and you have forgotten to use the proper idiom
        in the main module:
            if __name__ == '__main__':
                freeze_support()
                ...
        The "freeze_support()" line can be omitted if the program
        is not going to be frozen to produce an executable.
Traceback (most recent call last):
  File "/home/josyula/miniconda3/lib/python3.9/site-packages/wandb/sdk/wandb_init.py", line 931, in init
    run = wi.init()
  File "/home/josyula/miniconda3/lib/python3.9/site-packages/wandb/sdk/wandb_init.py", line 467, in init
    backend.ensure_launched()
  File "/home/josyula/miniconda3/lib/python3.9/site-packages/wandb/sdk/backend/backend.py", line 219, in ensure_launched
    self.wandb_process.start()
  File "/home/josyula/miniconda3/lib/python3.9/multiprocessing/process.py", line 121, in start
    self._popen = self._Popen(self)
  File "/home/josyula/miniconda3/lib/python3.9/multiprocessing/context.py", line 284, in _Popen
    return Popen(process_obj)
  File "/home/josyula/miniconda3/lib/python3.9/multiprocessing/popen_spawn_posix.py", line 32, in __init__
    super().__init__(process_obj)
  File "/home/josyula/miniconda3/lib/python3.9/multiprocessing/popen_fork.py", line 19, in __init__
    self._launch(process_obj)
  File "/home/josyula/miniconda3/lib/python3.9/multiprocessing/popen_spawn_posix.py", line 42, in _launch
    prep_data = spawn.get_preparation_data(process_obj._name)
  File "/home/josyula/miniconda3/lib/python3.9/multiprocessing/spawn.py", line 154, in get_preparation_data
    _check_not_importing_main()
  File "/home/josyula/miniconda3/lib/python3.9/multiprocessing/spawn.py", line 134, in _check_not_importing_main
    raise RuntimeError('''
RuntimeError:
        An attempt has been made to start a new process before the
        current process has finished its bootstrapping phase.
        This probably means that you are not using fork to start your
        child processes and you have forgotten to use the proper idiom
        in the main module:
            if __name__ == '__main__':
                freeze_support()
                ...
        The "freeze_support()" line can be omitted if the program
        is not going to be frozen to produce an executable.
[34m[1mwandb[39m[22m: Currently logged in as: [33mjosyulak[39m (use `wandb login --relogin` to force relogin)
Traceback (most recent call last):
  File "/home/josyula/miniconda3/lib/python3.9/site-packages/wandb/sdk/wandb_init.py", line 931, in init
    run = wi.init()
  File "/home/josyula/miniconda3/lib/python3.9/site-packages/wandb/sdk/wandb_init.py", line 467, in init
    backend.ensure_launched()
  File "/home/josyula/miniconda3/lib/python3.9/site-packages/wandb/sdk/backend/backend.py", line 219, in ensure_launched
    self.wandb_process.start()
  File "/home/josyula/miniconda3/lib/python3.9/multiprocessing/process.py", line 121, in start
    self._popen = self._Popen(self)
  File "/home/josyula/miniconda3/lib/python3.9/multiprocessing/context.py", line 284, in _Popen
    return Popen(process_obj)
  File "/home/josyula/miniconda3/lib/python3.9/multiprocessing/popen_spawn_posix.py", line 32, in __init__
    super().__init__(process_obj)
  File "/home/josyula/miniconda3/lib/python3.9/multiprocessing/popen_fork.py", line 19, in __init__
    self._launch(process_obj)
  File "/home/josyula/miniconda3/lib/python3.9/multiprocessing/popen_spawn_posix.py", line 42, in _launch
    prep_data = spawn.get_preparation_data(process_obj._name)
  File "/home/josyula/miniconda3/lib/python3.9/multiprocessing/spawn.py", line 154, in get_preparation_data
    _check_not_importing_main()
  File "/home/josyula/miniconda3/lib/python3.9/multiprocessing/spawn.py", line 134, in _check_not_importing_main
    raise RuntimeError('''
RuntimeError:
        An attempt has been made to start a new process before the
        current process has finished its bootstrapping phase.
        This probably means that you are not using fork to start your
        child processes and you have forgotten to use the proper idiom
        in the main module:
            if __name__ == '__main__':
                freeze_support()
                ...
        The "freeze_support()" line can be omitted if the program
        is not going to be frozen to produce an executable.
[34m[1mwandb[39m[22m: [32m[41mERROR[39m[49m Abnormal program exit
Traceback (most recent call last):
  File "/home/josyula/miniconda3/lib/python3.9/site-packages/wandb/sdk/wandb_init.py", line 931, in init
    run = wi.init()
  File "/home/josyula/miniconda3/lib/python3.9/site-packages/wandb/sdk/wandb_init.py", line 467, in init
    backend.ensure_launched()
  File "/home/josyula/miniconda3/lib/python3.9/site-packages/wandb/sdk/backend/backend.py", line 219, in ensure_launched
    self.wandb_process.start()
  File "/home/josyula/miniconda3/lib/python3.9/multiprocessing/process.py", line 121, in start
    self._popen = self._Popen(self)
  File "/home/josyula/miniconda3/lib/python3.9/multiprocessing/context.py", line 284, in _Popen
    return Popen(process_obj)
  File "/home/josyula/miniconda3/lib/python3.9/multiprocessing/popen_spawn_posix.py", line 32, in __init__
    super().__init__(process_obj)
  File "/home/josyula/miniconda3/lib/python3.9/multiprocessing/popen_fork.py", line 19, in __init__
    self._launch(process_obj)
  File "/home/josyula/miniconda3/lib/python3.9/multiprocessing/popen_spawn_posix.py", line 42, in _launch
    prep_data = spawn.get_preparation_data(process_obj._name)
  File "/home/josyula/miniconda3/lib/python3.9/multiprocessing/spawn.py", line 154, in get_preparation_data
    _check_not_importing_main()
  File "/home/josyula/miniconda3/lib/python3.9/multiprocessing/spawn.py", line 134, in _check_not_importing_main
    raise RuntimeError('''
RuntimeError:
        An attempt has been made to start a new process before the
        current process has finished its bootstrapping phase.
        This probably means that you are not using fork to start your
        child processes and you have forgotten to use the proper idiom
        in the main module:
            if __name__ == '__main__':
                freeze_support()
                ...
        The "freeze_support()" line can be omitted if the program
        is not going to be frozen to produce an executable.
The above exception was the direct cause of the following exception:
Traceback (most recent call last):
  File "/home/josyula/miniconda3/lib/python3.9/multiprocessing/spawn.py", line 125, in _main
    prepare(preparation_data)
  File "/home/josyula/miniconda3/lib/python3.9/multiprocessing/spawn.py", line 236, in prepare
    _fixup_main_from_path(data['init_main_from_path'])
  File "/home/josyula/miniconda3/lib/python3.9/multiprocessing/spawn.py", line 287, in _fixup_main_from_path
    main_content = runpy.run_path(main_path,
  File "/home/josyula/miniconda3/lib/python3.9/runpy.py", line 288, in run_path
    return _run_module_code(code, init_globals, run_name,
  File "/home/josyula/miniconda3/lib/python3.9/runpy.py", line 97, in _run_module_code
    _run_code(code, mod_globals, init_globals,
  File "/home/josyula/miniconda3/lib/python3.9/runpy.py", line 87, in _run_code
    exec(code, run_globals)
  File "/home/josyula/Programs/MAS_Project/gym_envs_urdf/examples/neurocoevolution_pytorch/main.py", line 4, in <module>
    from algorithms.trainer_ga import GATrainer
  File "/home/josyula/Programs/MAS_Project/gym_envs_urdf/examples/neurocoevolution_pytorch/algorithms/trainer_ga.py", line 17, in <module>
    wandb.init(project="neurocoevolution_mr_carry_hof_diff", entity="josyula", sync_tensorboard=True, config=DEFAULT_CONFIG)
  File "/home/josyula/miniconda3/lib/python3.9/site-packages/wandb/sdk/wandb_init.py", line 969, in init
    six.raise_from(Exception("problem"), error_seen)
  File "<string>", line 3, in raise_from
Exception: problem
[34m[1mwandb[39m[22m: [32m[41mERROR[39m[49m Abnormal program exit
Traceback (most recent call last):
  File "/home/josyula/miniconda3/lib/python3.9/site-packages/wandb/sdk/wandb_init.py", line 931, in init
    run = wi.init()
  File "/home/josyula/miniconda3/lib/python3.9/site-packages/wandb/sdk/wandb_init.py", line 467, in init
    backend.ensure_launched()
  File "/home/josyula/miniconda3/lib/python3.9/site-packages/wandb/sdk/backend/backend.py", line 219, in ensure_launched
    self.wandb_process.start()
  File "/home/josyula/miniconda3/lib/python3.9/multiprocessing/process.py", line 121, in start
    self._popen = self._Popen(self)
  File "/home/josyula/miniconda3/lib/python3.9/multiprocessing/context.py", line 284, in _Popen
    return Popen(process_obj)
  File "/home/josyula/miniconda3/lib/python3.9/multiprocessing/popen_spawn_posix.py", line 32, in __init__
    super().__init__(process_obj)
  File "/home/josyula/miniconda3/lib/python3.9/multiprocessing/popen_fork.py", line 19, in __init__
    self._launch(process_obj)
  File "/home/josyula/miniconda3/lib/python3.9/multiprocessing/popen_spawn_posix.py", line 42, in _launch
    prep_data = spawn.get_preparation_data(process_obj._name)
  File "/home/josyula/miniconda3/lib/python3.9/multiprocessing/spawn.py", line 154, in get_preparation_data
    _check_not_importing_main()
  File "/home/josyula/miniconda3/lib/python3.9/multiprocessing/spawn.py", line 134, in _check_not_importing_main
    raise RuntimeError('''
RuntimeError:
        An attempt has been made to start a new process before the
        current process has finished its bootstrapping phase.
        This probably means that you are not using fork to start your
        child processes and you have forgotten to use the proper idiom
        in the main module:
            if __name__ == '__main__':
                freeze_support()
                ...
        The "freeze_support()" line can be omitted if the program
        is not going to be frozen to produce an executable.
The above exception was the direct cause of the following exception:
Traceback (most recent call last):
  File "/home/josyula/miniconda3/lib/python3.9/multiprocessing/spawn.py", line 125, in _main
    prepare(preparation_data)
  File "/home/josyula/miniconda3/lib/python3.9/multiprocessing/spawn.py", line 236, in prepare
    _fixup_main_from_path(data['init_main_from_path'])
  File "/home/josyula/miniconda3/lib/python3.9/multiprocessing/spawn.py", line 287, in _fixup_main_from_path
    main_content = runpy.run_path(main_path,
  File "/home/josyula/miniconda3/lib/python3.9/runpy.py", line 288, in run_path
    return _run_module_code(code, init_globals, run_name,
  File "/home/josyula/miniconda3/lib/python3.9/runpy.py", line 97, in _run_module_code
    _run_code(code, mod_globals, init_globals,
  File "/home/josyula/miniconda3/lib/python3.9/runpy.py", line 87, in _run_code
    exec(code, run_globals)
  File "/home/josyula/Programs/MAS_Project/gym_envs_urdf/examples/neurocoevolution_pytorch/main.py", line 4, in <module>
    from algorithms.trainer_ga import GATrainer
  File "/home/josyula/Programs/MAS_Project/gym_envs_urdf/examples/neurocoevolution_pytorch/algorithms/trainer_ga.py", line 17, in <module>
    wandb.init(project="neurocoevolution_mr_carry_hof_diff", entity="josyula", sync_tensorboard=True, config=DEFAULT_CONFIG)
  File "/home/josyula/miniconda3/lib/python3.9/site-packages/wandb/sdk/wandb_init.py", line 969, in init
    six.raise_from(Exception("problem"), error_seen)
  File "<string>", line 3, in raise_from
Exception: problem
[34m[1mwandb[39m[22m: [32m[41mERROR[39m[49m Abnormal program exit
Traceback (most recent call last):
  File "/home/josyula/miniconda3/lib/python3.9/site-packages/wandb/sdk/wandb_init.py", line 931, in init
    run = wi.init()
  File "/home/josyula/miniconda3/lib/python3.9/site-packages/wandb/sdk/wandb_init.py", line 467, in init
    backend.ensure_launched()
  File "/home/josyula/miniconda3/lib/python3.9/site-packages/wandb/sdk/backend/backend.py", line 219, in ensure_launched
    self.wandb_process.start()
  File "/home/josyula/miniconda3/lib/python3.9/multiprocessing/process.py", line 121, in start
    self._popen = self._Popen(self)
  File "/home/josyula/miniconda3/lib/python3.9/multiprocessing/context.py", line 284, in _Popen
    return Popen(process_obj)
  File "/home/josyula/miniconda3/lib/python3.9/multiprocessing/popen_spawn_posix.py", line 32, in __init__
    super().__init__(process_obj)
  File "/home/josyula/miniconda3/lib/python3.9/multiprocessing/popen_fork.py", line 19, in __init__
    self._launch(process_obj)
  File "/home/josyula/miniconda3/lib/python3.9/multiprocessing/popen_spawn_posix.py", line 42, in _launch
    prep_data = spawn.get_preparation_data(process_obj._name)
  File "/home/josyula/miniconda3/lib/python3.9/multiprocessing/spawn.py", line 154, in get_preparation_data
    _check_not_importing_main()
  File "/home/josyula/miniconda3/lib/python3.9/multiprocessing/spawn.py", line 134, in _check_not_importing_main
    raise RuntimeError('''
RuntimeError:
        An attempt has been made to start a new process before the
        current process has finished its bootstrapping phase.
        This probably means that you are not using fork to start your
        child processes and you have forgotten to use the proper idiom
        in the main module:
            if __name__ == '__main__':
                freeze_support()
                ...
        The "freeze_support()" line can be omitted if the program
        is not going to be frozen to produce an executable.
The above exception was the direct cause of the following exception:
Traceback (most recent call last):
  File "/home/josyula/miniconda3/lib/python3.9/multiprocessing/spawn.py", line 125, in _main
    prepare(preparation_data)
  File "/home/josyula/miniconda3/lib/python3.9/multiprocessing/spawn.py", line 236, in prepare
    _fixup_main_from_path(data['init_main_from_path'])
  File "/home/josyula/miniconda3/lib/python3.9/multiprocessing/spawn.py", line 287, in _fixup_main_from_path
    main_content = runpy.run_path(main_path,
  File "/home/josyula/miniconda3/lib/python3.9/runpy.py", line 288, in run_path
    return _run_module_code(code, init_globals, run_name,
  File "/home/josyula/miniconda3/lib/python3.9/runpy.py", line 97, in _run_module_code
    _run_code(code, mod_globals, init_globals,
  File "/home/josyula/miniconda3/lib/python3.9/runpy.py", line 87, in _run_code
    exec(code, run_globals)
  File "/home/josyula/Programs/MAS_Project/gym_envs_urdf/examples/neurocoevolution_pytorch/main.py", line 4, in <module>
    from algorithms.trainer_ga import GATrainer
  File "/home/josyula/Programs/MAS_Project/gym_envs_urdf/examples/neurocoevolution_pytorch/algorithms/trainer_ga.py", line 17, in <module>
    wandb.init(project="neurocoevolution_mr_carry_hof_diff", entity="josyula", sync_tensorboard=True, config=DEFAULT_CONFIG)
  File "/home/josyula/miniconda3/lib/python3.9/site-packages/wandb/sdk/wandb_init.py", line 969, in init
    six.raise_from(Exception("problem"), error_seen)
  File "<string>", line 3, in raise_from
Exception: problem
[34m[1mwandb[39m[22m: [32m[41mERROR[39m[49m Abnormal program exit
Traceback (most recent call last):
  File "/home/josyula/miniconda3/lib/python3.9/site-packages/wandb/sdk/wandb_init.py", line 931, in init
    run = wi.init()
  File "/home/josyula/miniconda3/lib/python3.9/site-packages/wandb/sdk/wandb_init.py", line 467, in init
    backend.ensure_launched()
  File "/home/josyula/miniconda3/lib/python3.9/site-packages/wandb/sdk/backend/backend.py", line 219, in ensure_launched
    self.wandb_process.start()
  File "/home/josyula/miniconda3/lib/python3.9/multiprocessing/process.py", line 121, in start
    self._popen = self._Popen(self)
  File "/home/josyula/miniconda3/lib/python3.9/multiprocessing/context.py", line 284, in _Popen
    return Popen(process_obj)
  File "/home/josyula/miniconda3/lib/python3.9/multiprocessing/popen_spawn_posix.py", line 32, in __init__
    super().__init__(process_obj)
  File "/home/josyula/miniconda3/lib/python3.9/multiprocessing/popen_fork.py", line 19, in __init__
    self._launch(process_obj)
  File "/home/josyula/miniconda3/lib/python3.9/multiprocessing/popen_spawn_posix.py", line 42, in _launch
    prep_data = spawn.get_preparation_data(process_obj._name)
  File "/home/josyula/miniconda3/lib/python3.9/multiprocessing/spawn.py", line 154, in get_preparation_data
    _check_not_importing_main()
  File "/home/josyula/miniconda3/lib/python3.9/multiprocessing/spawn.py", line 134, in _check_not_importing_main
    raise RuntimeError('''
RuntimeError:
        An attempt has been made to start a new process before the
        current process has finished its bootstrapping phase.
        This probably means that you are not using fork to start your
        child processes and you have forgotten to use the proper idiom
        in the main module:
            if __name__ == '__main__':
                freeze_support()
                ...
        The "freeze_support()" line can be omitted if the program
        is not going to be frozen to produce an executable.
The above exception was the direct cause of the following exception:
Traceback (most recent call last):
  File "/home/josyula/miniconda3/lib/python3.9/multiprocessing/spawn.py", line 125, in _main
    prepare(preparation_data)
  File "/home/josyula/miniconda3/lib/python3.9/multiprocessing/spawn.py", line 236, in prepare
    _fixup_main_from_path(data['init_main_from_path'])
  File "/home/josyula/miniconda3/lib/python3.9/multiprocessing/spawn.py", line 287, in _fixup_main_from_path
    main_content = runpy.run_path(main_path,
  File "/home/josyula/miniconda3/lib/python3.9/runpy.py", line 288, in run_path
    return _run_module_code(code, init_globals, run_name,
  File "/home/josyula/miniconda3/lib/python3.9/runpy.py", line 97, in _run_module_code
    _run_code(code, mod_globals, init_globals,
  File "/home/josyula/miniconda3/lib/python3.9/runpy.py", line 87, in _run_code
    exec(code, run_globals)
  File "/home/josyula/Programs/MAS_Project/gym_envs_urdf/examples/neurocoevolution_pytorch/main.py", line 4, in <module>
    from algorithms.trainer_ga import GATrainer
  File "/home/josyula/Programs/MAS_Project/gym_envs_urdf/examples/neurocoevolution_pytorch/algorithms/trainer_ga.py", line 17, in <module>
    wandb.init(project="neurocoevolution_mr_carry_hof_diff", entity="josyula", sync_tensorboard=True, config=DEFAULT_CONFIG)
  File "/home/josyula/miniconda3/lib/python3.9/site-packages/wandb/sdk/wandb_init.py", line 969, in init
    six.raise_from(Exception("problem"), error_seen)
  File "<string>", line 3, in raise_from
Exception: problem
Traceback (most recent call last):
  File "/home/josyula/Programs/MAS_Project/gym_envs_urdf/examples/neurocoevolution_pytorch/main.py", line 17, in <module>
    trainer.step()
  File "/home/josyula/Programs/MAS_Project/gym_envs_urdf/examples/neurocoevolution_pytorch/algorithms/trainer_es.py", line 67, in step
    mutations_player1 += [mutation_pool.map(self.worker_class.mutate_individual, temp)]
  File "/home/josyula/miniconda3/lib/python3.9/multiprocessing/pool.py", line 364, in map
    return self._map_async(func, iterable, mapstar, chunksize).get()
  File "/home/josyula/miniconda3/lib/python3.9/multiprocessing/pool.py", line 765, in get
    self.wait(timeout)
  File "/home/josyula/miniconda3/lib/python3.9/multiprocessing/pool.py", line 762, in wait
    self._event.wait(timeout)
